Workbook

Sheet 01_Raw
A1: ID | B1: Customer_Name | C1: Order_ID | D1: Order_Date | E1: Product | F1: Category | G1: Quantity | H1: Price | I1: Payment_Method | J1: Status | K1: Total
A2: 100 | B2: Customer_100 | C2: ORD-41285 | D2: 11/22/2024 | E2: Blender | F2: Home | G2: 3 | H2: 38 | I2: Cash on Delivery | J2: Shipped | K2: 114
A3: 101 | B3: Customer_101 | C3: ORD-35783 | D3: 7/5/2025 | E3: Smartphone | F3: Electronics | G3: 2 | H3: abd | I3: PayPal | J3: Processing
A4: 102 | B4: Customer_102 | C4: ORD-84355 | D4: 12/23/2024 | E4: Tennis Racket | F4: Sports | G4: 1 | H4: 389.05 | I4: PayPal | J4: Delivered | K4: 389.05
A5: 103 | B5: Customer_103 | C5: ORD-57811 | D5: 3/19/2025 | E5: Science | F5: Books | G5: 5 | H5: 233.92 | I5: PayPal | J5: Processing | K5: 1169.6
A6: 104 | B6: Customer_104 | C6: ORD-93614 | D6: 10/20/2025 | E6: Biography | F6: Books | G6: 1 | H6: 552.51 | I6: Cash on Delivery | J6: Processing | K6: 552.51
A7: 105 | B7: Customer_105 | C7: ORD-22442 | D7: 11/20/2024 | E7: Tennis Racket | F7: Sports | G7: 3 | H7: 122.06 | I7: Cash on Delivery | J7: Cancelled | K7: 366.18
A8: 106 | B8: Customer_106 | C8: ORD-25885 | D8: 2/2/2025 | E8: Blender | F8: Home | H8: 978.63 | I8: Bank Transfer | J8: Processing
A9: 107 | B9: Customer_107 | C9: ORD-89122 | D9: 1/3/2025 | E9: Biography | F9: Books | G9: 5 | H9: 587.68 | I9: PayPal | J9: Returned | K9: 2938.4
A10: 108 | B10: Customer_108 | C10: ORD-64400 | D10: 10/23/2025 | E10: Science | F10: Books | G10: 1 | H10: 600.29 | I10: Cash on Delivery | J10: Processing | K10: 600.29
A11: 109 | B11: Customer_109 | C11: ORD-18512 | D11: 5/3/2025 | E11: Tennis Racket | F11: Sports | G11: 5 | H11: 168.34 | I11: Credit Card | J11: Shipped | K11: 841.7
A12: 110 | B12: Customer_110 | C12: ORD-61020 | D12: 9/26/2025 | E12: Basketball | F12: sports | G12: 5 | H12: four hundred | I12: Cash on Delivery | J12: Cancelled
A13: 111 | B13: Customer_111 | C13: ORD-72349 | D13: 10/22/2025 | E13: Comics | F13: Books | G13: 2 | H13: 865.77 | I13: Credit Card | J13: Returned | K13: 1731.54
A14: 112 | B14: Customer_112 | C14: ORD-80867 | D14: 3/2/2025 | E14: Shoes | F14: Clothing | G14: 4 | H14: 752.13 | I14: Bank Transfer | J14: Delivered | K14: 3008.52
A15: 113 | B15: Customer_113 | C15: ORD-23994 | D15: 7/24/2025 | E15: Fiction | F15: Books | G15: 1 | H15: 411.81 | I15: Credit Card | J15: Processing | K15: 411.81
A16: 114 | B16: Customer_114 | C16: ORD-77417 | D16: Jan 5 2023 | E16: Smartphone | F16: Electronics | G16: 2 | H16: 413.13 | I16: Cash on Delivery | J16: Shipped | K16: 826.26
A17: 115 | B17: Customer_115 | C17: ORD-72778 | D17: 1/10/2025 | E17: Fiction | F17: Books | G17: 2 | H17: 796.84 | I17: Cash on Delivery | J17: Returned | K17: 1115.576
A18: 116 | B18: Customer_116 | C18: ORD-63660 | D18: 10/30/2025 | E18: Microwave | F18: Home | G18: 4 | I18: Cash on Delivery | J18: Processing
A19: 117 | B19: Customer_117 | C19: ORD-72751 | D19: 2/12/2025 | E19: Blender | F19: electronic | G19: -2 | H19: 10000 | I19: Cash on Delivery | J19: Processing | K19: -20000
A20: 118 | B20: Customer_118 | C20: ORD-96061 | D20: 5/31/2025 | E20: Science | F20: Books | G20: 5 | H20: 247.82 | I20: PayPal | J20: Processing | K20: 1239.1
A21: 119 | B21: Customer_119 | C21: ORD-76016 | D21: 12/19/2024 | E21: Basketball | F21: Sports | G21: 4 | H21: 438.19 | I21: Cash on Delivery | J21: Processing | K21: 1752.76
A22: 120 | B22: Customer_120 | C22: ORD-14659 | D22: 6/13/2025 | E22: Yoga Mat | F22: ELECTRONICS | G22: 5 | H22: 300$ | I22: Credit Card | J22: Cancelled
A23: 121 | B23: Customer_121 | C23: ORD-80067 | D23: 10/11/2025 | E23: Basketball | F23: Sports | G23: 4 | H23: 523.01 | I23: Credit Card | J23: Delivered | K23: 2092.04
A24: 122 | B24: Customer_122 | C24: ORD-21443 | D24: 5/16/2025 | E24: Microwave | F24: Home | G24: 2 | H24: 556.93 | I24: PayPal | J24: Shipped | K24: 1113.86
A25: 123 | B25: Customer_123 | C25: ORD-11314 | D25: 10/6/2025 | E25: Vacuum | F25: electronic | G25: 3 | H25: 615.91 | I25: Cash on Delivery | J25: Cancelled | K25: 1847.73
A26: 124 | B26: Customer_124 | C26: ORD-46136 | D26: 5/31/2025 | E26: Comics | F26: Books | G26: 5 | I26: PayPal | J26: Cancelled
A27: 125 | B27: Customer_125 | C27: ORD-23202 | D27: 2/9/2025 | E27: Comics | F27: Books | G27: 4 | H27: 765.69 | I27: PayPal | J27: Shipped | K27: 3062.76
A28: 126 | B28: Customer_126 | C28: ORD-11261 | D28: 5/18/2025 | E28: Shoes | F28: Clothing | G28: 4 | H28: 836.8 | I28: Bank Transfer | J28: Cancelled | K28: 3347.2
A29: 127 | B29: Customer_127 | C29: ORD-65482 | D29: 5/12/2025 | E29: Blender | F29: Home | G29: 5 | H29: 336.02 | I29: Bank Transfer | J29: Returned | K29: 1680.1
A30: 128 | B30: Customer_128 | C30: ORD-12270 | D30: 11/10/2024 | E30: Lamp | F30: electronics | G30: 3 | H30: 898.69 | I30: Bank Transfer | J30: Delivered | K30: 2696.07
A31: 129 | B31: Customer_129 | C31: ORD-48863 | D31: 6/22/2025 | E31: Science | F31: Books | G31: 4 | H31: 736.71 | I31: Bank Transfer | J31: Returned | K31: 2946.84
A32: 130 | B32: Customer_130 | C32: ORD-34007 | D32: 8/15/2025 | E32: Tennis Racket | F32: Sports | G32: 2 | I32: Bank Transfer | J32: Processing
A33: 131 | B33: Customer_131 | C33: ORD-91396 | D33: 6/11/2025 | E33: Lamp | F33: Home | G33: 5 | H33: 616.63 | I33: PayPal | J33: Shipped | K33: 3083.15
A34: 132 | B34: Customer_132 | C34: ORD-40186 | D34: 4/2/2025 | E34: Yoga Mat | F34: ELECTRONICS | G34: 1 | H34: 266.7 | I34: PayPal | J34: Delivered | K34: 266.7
A35: 133 | B35: Customer_133 | C35: ORD-68182 | D35: 12/5/2024 | E35: Biography | F35: nan | G35: 5 | H35: 343.24 | I35: Credit Card | J35: Shipped | K35: 1716.2
A36: 134 | B36: Customer_134 | C36: ORD-16585 | D36: 10/4/2025 | E36: T-shirt | F36: Clothing | G36: -5 | H36: 591.53 | I36: PayPal | J36: Shipped | K36: -2957.65
A37: 135 | B37: Customer_135 | C37: ORD-33656 | D37: 2/9/2025 | E37: Smartwatch | F37: electronics | G37: 4 | H37: 446.19 | I37: Cash on Delivery | J37: Cancelled | K37: 1784.76
A38: 136 | B38: Customer_136 | C38: ORD-20985 | D38: 6/12/2025 | E38: Headphones | G38: 1 | H38: 696.71 | I38: Credit Card | J38: Delivered | K38: 696.71
A39: 137 | B39: Customer_137 | C39: ORD-91254 | D39: 2/23/2025 | E39: Vacuum | F39: Home | G39: 3 | H39: -100 | I39: Cash on Delivery | J39: Delivered | K39: -300
A40: 138 | B40: Customer_138 | C40: ORD-34319 | D40: 8/9/2025 | E40: Lamp | F40: Home | G40: 1 | H40: 531.06 | I40: PayPal | J40: Processing | K40: 531.06
...

Sheet 02_Audit
A1: Issue | B1: Column(s) | C1: Records Affected | D1: Decision
A2: Leading spaces in headers | B2: Customer_Name, Category | C2: 2 columns | D2: Renamed manually to clean headers
A3: Inconsistent text casing | B3: Category | C3: 9 distinct values | D3: Standardized with TRIM + PROPER → 5 valid categories
A4: Misspelled category ("electronic") | B4: Category | C4: - | D4: Corrected to "Electronics" via IF
A5: Nulls stored as literal "nan" | B5: Category | C5: 2 | D5: Flagged as "Missing" (source export artifact)
A6: Empty strings vs true blanks | B6: Price, Quantity, Category, Total | C6: - | D6: Detected with LEN(TRIM())=0; ISBLANK failed to catch them
A7: Missing Values | B7: Category 8 · Quantity 5 · Price 5 · Total 14 | C7: 32 | D7: Labeled "Missing", not deleted
A8: Non-numeric values | B8: Price ("abd" ×2, "four hundred"), Quantity ("4a") | C8: 4 | D8: Flagged "Invalid" — not guessed
A9: Currency symbol in value | B9: Price ("300$") | C9: 1 | D9: Removed with SUBSTITUTE → 300
A10: US decimal notation (period) | B10: Price, Total | C10: all | D10: Converted to regional separator before VALUE
A11: Inconsistent date formats | B11: Order_Date | C11: 2 | D11: "Jan 5 2023" corrected manually; "abc" flagged Invalid
A12: Regional date misparse risk | B12: Order_Date | C12: all | D12: Excel read M/D as D/M causing silent errors; parsed explicitly with FIND/LEFT/MID/RIGHT + DATE, standardized to ISO YYYY-MM-DD
A13: Exact duplicate row | B13: All | C13: 1 (ID 146) | D13: Removed one copy
A14: Duplicate IDs with differing data | B14: ID, Order_ID | C14: 2 (IDs 142, 175) | D14: Validated against Quantity × Price; kept the correct record — an automated "remove duplicates" would have retained corrupted data
A15: Negative values | B15: Quantity (-2, -5), Price (-100) | C15: 3 | D15: Logically impossible but technically valid; flagged for client review, not altered
A16: Outlier price (10,000) | B16: Price | C16: 1 | D16: Flagged for review (10-20× typical range)
A17: Total ≠ Quantity × Price | B17: Total | C17: 3 (IDs 115, 151, 185) | D17: Exactly 70% of calculated value — consistent pattern suggesting an unrecorded discount; flagged, not overwritten
A18: Recoverable Total | B18: Total | C18: 1 | D18: Recalculated from Quantity × Price where inputs were clean

Sheet 99_Reference_Formulas
A1: ID | B1: Customer_Name | C1: Order_ID | D1: Order_Date | E1: Product | F1: Category | G1: Quantity | H1: Price | I1: Payment_Method | J1: Status | K1: Total | N1: =ISNUMBER('01_Raw'!D2) -> FALSE | P1: =LEFT('01_Raw'!D2, FIND("/",'01_Raw'!D2) - 1) -> 11 | Q1: =IFERROR(RIGHT('01_Raw'!D2,4),"Invalid") -> 2024 | R1: =MID('01_Raw'!D2,FIND("/",'01_Raw'!D2) + 1,FIND("/",'01_Raw'!D2,FIND("/",'01_Raw'!D2)+1)-FIND("/",'01_Raw'!D2)-1) -> 22 | S1: =IFERROR(DATE(Q1,P1,R1),"Invalid") -> 45618 | U1: =IFERROR(VALUE(SUBSTITUTE(SUBSTITUTE('01_Raw'!H2,"$",""), ".",",")),"Invalid") -> 38 | V1: =IFERROR(VALUE('01_Raw'!G2), "Invalid") -> 3 | X1: =IF(ISBLANK('01_Raw'!H2),"Missing", IFERROR(VALUE(SUBSTITUTE(SUBSTITUTE('01_Raw'!H2,"$",""), ".",",")),"Invalid")) -> 38 | Y1: =IF(LEN(TRIM('01_Raw'!H2)) = 0, "Missing",IFERROR(VALUE(SUBSTITUTE(SUBSTITUTE('01_Raw'!H2,"$",""), ".",",")),"Invalid")) -> 38 | AA1: =IF(LEN(TRIM('01_Raw'!G2)) = 0, "Missing",IFERROR(VALUE(SUBSTITUTE(SUBSTITUTE('01_Raw'!G2,"$",""), ".",",")),"Invalid")) -> 3 | AC1: =COUNTIF($A$2:$A$103,A2) -> 1 | AE1: =COUNTIF(messy_ecommerce_sales_data__2[Order_ID],'01_Raw'!C2) -> 1 | AG1: =IFERROR(AA1*Y1,"Cannot Calculate") -> 114 | AH1: =IF(AG1='01_Raw'!K2,"OK","Mismatch") -> Mismatch | AJ1: =IF(LEN(TRIM(AG1)) = 0, "Missing",IFERROR(VALUE(SUBSTITUTE(SUBSTITUTE(AG1,"$",""), ".",",")),"Invalid")) -> 114 | AK1: =IF(AJ1=AG1,"OK","Mismatch") -> OK
A2: ='01_Raw'!A2 -> 100 | B2: =TRIM('01_Raw'!B2) -> Customer_100 | D2: =IFERROR(DATE(Q1,P1,R1),"Invalid") -> 45618 | E2: =TRIM('01_Raw'!E2) -> Blender | F2: =IF(PROPER(TRIM('01_Raw'!F2))="Electronic","Electronics",PROPER(TRIM('01_Raw'!F2))) -> Home | I2: =TRIM('01_Raw'!I2) -> Cash on Delivery | J2: =TRIM('01_Raw'!J2) -> Shipped | N2: =ISNUMBER('01_Raw'!D3) -> FALSE | P2: =LEFT('01_Raw'!D3, FIND("/",'01_Raw'!D3) - 1) -> 7 | Q2: =IFERROR(RIGHT('01_Raw'!D3,4),"Invalid") -> 2025 | R2: =MID('01_Raw'!D3,FIND("/",'01_Raw'!D3) + 1,FIND("/",'01_Raw'!D3,FIND("/",'01_Raw'!D3)+1)-FIND("/",'01_Raw'!D3)-1) -> 5 | S2: =IFERROR(DATE(Q2,P2,R2),"Invalid") -> 45843 | U2: =IFERROR(VALUE(SUBSTITUTE(SUBSTITUTE('01_Raw'!H3,"$",""), ".",",")),"Invalid") -> Invalid | V2: =IFERROR(VALUE('01_Raw'!G3), "Invalid") -> 2 | X2: =IF(ISBLANK('01_Raw'!H3),"Missing", IFERROR(VALUE(SUBSTITUTE(SUBSTITUTE('01_Raw'!H3,"$",""), ".",",")),"Invalid")) -> Invalid | Y2: =IF(LEN(TRIM('01_Raw'!H3)) = 0, "Missing",IFERROR(VALUE(SUBSTITUTE(SUBSTITUTE('01_Raw'!H3,"$",""), ".",",")),"Invalid")) -> Invalid | AA2: =IF(LEN(TRIM('01_Raw'!G3)) = 0, "Missing",IFERROR(VALUE(SUBSTITUTE(SUBSTITUTE('01_Raw'!G3,"$",""), ".",",")),"Invalid")) -> 2 | AC2: =COUNTIF($A$2:$A$103,A3) -> 1 | AE2: =COUNTIF(messy_ecommerce_sales_data__2[Order_ID],'01_Raw'!C3) -> 1 | AG2: =IFERROR(AA2*Y2,"Cannot Calculate") -> Cannot Calculate | AH2: =IF(AG2='01_Raw'!K3,"OK","Mismatch") -> Mismatch | AJ2: =IF(LEN(TRIM(AG2)) = 0, "Missing",IFERROR(VALUE(SUBSTITUTE(SUBSTITUTE(AG2,"$",""), ".",",")),"Invalid")) -> Invalid | AK2: =IF(AJ2=AG2,"OK","Mismatch") -> Mismatch
A3: ='01_Raw'!A3 -> 101 | B3: =TRIM('01_Raw'!B3) -> Customer_101 | D3: =IFERROR(DATE(Q2,P2,R2),"Invalid") -> 45843 | E3: =TRIM('01_Raw'!E3) -> Smartphone | F3: =IF(PROPER(TRIM('01_Raw'!F3))="Electronic","Electronics",PROPER(TRIM('01_Raw'!F3))) -> Electronics | I3: =TRIM('01_Raw'!I3) -> PayPal | J3: =TRIM('01_Raw'!J3) -> Processing | N3: =ISNUMBER('01_Raw'!D4) -> FALSE | P3: =LEFT('01_Raw'!D4, FIND("/",'01_Raw'!D4) - 1) -> 12 | Q3: =IFERROR(RIGHT('01_Raw'!D4,4),"Invalid") -> 2024 | R3: =MID('01_Raw'!D4,FIND("/",'01_Raw'!D4) + 1,FIND("/",'01_Raw'!D4,FIND("/",'01_Raw'!D4)+1)-FIND("/",'01_Raw'!D4)-1) -> 23 | S3: =IFERROR(DATE(Q3,P3,R3),"Invalid") -> 45649 | U3: =IFERROR(VALUE(SUBSTITUTE(SUBSTITUTE('01_Raw'!H4,"$",""), ".",",")),"Invalid") -> 389.05 | V3: =IFERROR(VALUE('01_Raw'!G4), "Invalid") -> 1 | X3: =IF(ISBLANK('01_Raw'!H4),"Missing", IFERROR(VALUE(SUBSTITUTE(SUBSTITUTE('01_Raw'!H4,"$",""), ".",",")),"Invalid")) -> 389.05 | Y3: =IF(LEN(TRIM('01_Raw'!H4)) = 0, "Missing",IFERROR(VALUE(SUBSTITUTE(SUBSTITUTE('01_Raw'!H4,"$",""), ".",",")),"Invalid")) -> 389.05 | AA3: =IF(LEN(TRIM('01_Raw'!G4)) = 0, "Missing",IFERROR(VALUE(SUBSTITUTE(SUBSTITUTE('01_Raw'!G4,"$",""), ".",",")),"Invalid")) -> 1 | AC3: =COUNTIF($A$2:$A$103,A4) -> 1 | AE3: =COUNTIF(messy_ecommerce_sales_data__2[Order_ID],'01_Raw'!C4) -> 1 | AG3: =IFERROR(AA3*Y3,"Cannot Calculate") -> 389.05 | AH3: =IF(AG3='01_Raw'!K4,"OK","Mismatch") -> Mismatch | AJ3: =IF(LEN(TRIM(AG3)) = 0, "Missing",IFERROR(VALUE(SUBSTITUTE(SUBSTITUTE(AG3,"$",""), ".",",")),"Invalid")) -> 389.05 | AK3: =IF(AJ3=AG3,"OK","Mismatch") -> OK
A4: ='01_Raw'!A4 -> 102 | B4: =TRIM('01_Raw'!B4) -> Customer_102 | D4: =IFERROR(DATE(Q3,P3,R3),"Invalid") -> 45649 | E4: =TRIM('01_Raw'!E4) -> Tennis Racket | F4: =IF(PROPER(TRIM('01_Raw'!F4))="Electronic","Electronics",PROPER(TRIM('01_Raw'!F4))) -> Sports | I4: =TRIM('01_Raw'!I4) -> PayPal | J4: =TRIM('01_Raw'!J4) -> Delivered | N4: =ISNUMBER('01_Raw'!D5) -> FALSE | P4: =LEFT('01_Raw'!D5, FIND("/",'01_Raw'!D5) - 1) -> 3 | Q4: =IFERROR(RIGHT('01_Raw'!D5,4),"Invalid") -> 2025 | R4: =MID('01_Raw'!D5,FIND("/",'01_Raw'!D5) + 1,FIND("/",'01_Raw'!D5,FIND("/",'01_Raw'!D5)+1)-FIND("/",'01_Raw'!D5)-1) -> 19 | S4: =IFERROR(DATE(Q4,P4,R4),"Invalid") -> 45735 | U4: =IFERROR(VALUE(SUBSTITUTE(SUBSTITUTE('01_Raw'!H5,"$",""), ".",",")),"Invalid") -> 233.92 | V4: =IFERROR(VALUE('01_Raw'!G5), "Invalid") -> 5 | X4: =IF(ISBLANK('01_Raw'!H5),"Missing", IFERROR(VALUE(SUBSTITUTE(SUBSTITUTE('01_Raw'!H5,"$",""), ".",",")),"Invalid")) -> 233.92 | Y4: =IF(LEN(TRIM('01_Raw'!H5)) = 0, "Missing",IFERROR(VALUE(SUBSTITUTE(SUBSTITUTE('01_Raw'!H5,"$",""), ".",",")),"Invalid")) -> 233.92 | AA4: =IF(LEN(TRIM('01_Raw'!G5)) = 0, "Missing",IFERROR(VALUE(SUBSTITUTE(SUBSTITUTE('01_Raw'!G5,"$",""), ".",",")),"Invalid")) -> 5 | AC4: =COUNTIF($A$2:$A$103,A5) -> 1 | AE4: =COUNTIF(messy_ecommerce_sales_data__2[Order_ID],'01_Raw'!C5) -> 1 | AG4: =IFERROR(AA4*Y4,"Cannot Calculate") -> 1169.6 | AH4: =IF(AG4='01_Raw'!K5,"OK","Mismatch") -> Mismatch | AJ4: =IF(LEN(TRIM(AG4)) = 0, "Missing",IFERROR(VALUE(SUBSTITUTE(SUBSTITUTE(AG4,"$",""), ".",",")),"Invalid")) -> 1169.6 | AK4: =IF(AJ4=AG4,"OK","Mismatch") -> OK
A5: ='01_Raw'!A5 -> 103 | B5: =TRIM('01_Raw'!B5) -> Customer_103 | D5: =IFERROR(DATE(Q4,P4,R4),"Invalid") -> 45735 | E5: =TRIM('01_Raw'!E5) -> Science | F5: =IF(PROPER(TRIM('01_Raw'!F5))="Electronic","Electronics",PROPER(TRIM('01_Raw'!F5))) -> Books | I5: =TRIM('01_Raw'!I5) -> PayPal | J5: =TRIM('01_Raw'!J5) -> Processing | N5: =ISNUMBER('01_Raw'!D6) -> FALSE | P5: =LEFT('01_Raw'!D6, FIND("/",'01_Raw'!D6) - 1) -> 10 | Q5: =IFERROR(RIGHT('01_Raw'!D6,4),"Invalid") -> 2025 | R5: =MID('01_Raw'!D6,FIND("/",'01_Raw'!D6) + 1,FIND("/",'01_Raw'!D6,FIND("/",'01_Raw'!D6)+1)-FIND("/",'01_Raw'!D6)-1) -> 20 | S5: =IFERROR(DATE(Q5,P5,R5),"Invalid") -> 45950 | U5: =IFERROR(VALUE(SUBSTITUTE(SUBSTITUTE('01_Raw'!H6,"$",""), ".",",")),"Invalid") -> 552.51 | V5: =IFERROR(VALUE('01_Raw'!G6), "Invalid") -> 1 | X5: =IF(ISBLANK('01_Raw'!H6),"Missing", IFERROR(VALUE(SUBSTITUTE(SUBSTITUTE('01_Raw'!H6,"$",""), ".",",")),"Invalid")) -> 552.51 | Y5: =IF(LEN(TRIM('01_Raw'!H6)) = 0, "Missing",IFERROR(VALUE(SUBSTITUTE(SUBSTITUTE('01_Raw'!H6,"$",""), ".",",")),"Invalid")) -> 552.51 | AA5: =IF(LEN(TRIM('01_Raw'!G6)) = 0, "Missing",IFERROR(VALUE(SUBSTITUTE(SUBSTITUTE('01_Raw'!G6,"$",""), ".",",")),"Invalid")) -> 1 | AC5: =COUNTIF($A$2:$A$103,A6) -> 1 | AE5: =COUNTIF(messy_ecommerce_sales_data__2[Order_ID],'01_Raw'!C6) -> 1 | AG5: =IFERROR(AA5*Y5,"Cannot Calculate") -> 552.51 | AH5: =IF(AG5='01_Raw'!K6,"OK","Mismatch") -> Mismatch | AJ5: =IF(LEN(TRIM(AG5)) = 0, "Missing",IFERROR(VALUE(SUBSTITUTE(SUBSTITUTE(AG5,"$",""), ".",",")),"Invalid")) -> 552.51 | AK5: =IF(AJ5=AG5,"OK","Mismatch") -> OK
A6: ='01_Raw'!A6 -> 104 | B6: =TRIM('01_Raw'!B6) -> Customer_104 | D6: =IFERROR(DATE(Q5,P5,R5),"Invalid") -> 45950 | E6: =TRIM('01_Raw'!E6) -> Biography | F6: =IF(PROPER(TRIM('01_Raw'!F6))="Electronic","Electronics",PROPER(TRIM('01_Raw'!F6))) -> Books | I6: =TRIM('01_Raw'!I6) -> Cash on Delivery | J6: =TRIM('01_Raw'!J6) -> Processing | N6: =ISNUMBER('01_Raw'!D7) -> FALSE | P6: =LEFT('01_Raw'!D7, FIND("/",'01_Raw'!D7) - 1) -> 11 | Q6: =IFERROR(RIGHT('01_Raw'!D7,4),"Invalid") -> 2024 | R6: =MID('01_Raw'!D7,FIND("/",'01_Raw'!D7) + 1,FIND("/",'01_Raw'!D7,FIND("/",'01_Raw'!D7)+1)-FIND("/",'01_Raw'!D7)-1) -> 20 | S6: =IFERROR(DATE(Q6,P6,R6),"Invalid") -> 45616 | U6: =IFERROR(VALUE(SUBSTITUTE(SUBSTITUTE('01_Raw'!H7,"$",""), ".",",")),"Invalid") -> 122.06 | V6: =IFERROR(VALUE('01_Raw'!G7), "Invalid") -> 3 | X6: =IF(ISBLANK('01_Raw'!H7),"Missing", IFERROR(VALUE(SUBSTITUTE(SUBSTITUTE('01_Raw'!H7,"$",""), ".",",")),"Invalid")) -> 122.06 | Y6: =IF(LEN(TRIM('01_Raw'!H7)) = 0, "Missing",IFERROR(VALUE(SUBSTITUTE(SUBSTITUTE('01_Raw'!H7,"$",""), ".",",")),"Invalid")) -> 122.06 | AA6: =IF(LEN(TRIM('01_Raw'!G7)) = 0, "Missing",IFERROR(VALUE(SUBSTITUTE(SUBSTITUTE('01_Raw'!G7,"$",""), ".",",")),"Invalid")) -> 3 | AC6: =COUNTIF($A$2:$A$103,A7) -> 1 | AE6: =COUNTIF(messy_ecommerce_sales_data__2[Order_ID],'01_Raw'!C7) -> 1 | AG6: =IFERROR(AA6*Y6,"Cannot Calculate") -> 366.18 | AH6: =IF(AG6='01_Raw'!K7,"OK","Mismatch") -> Mismatch | AJ6: =IF(LEN(TRIM(AG6)) = 0, "Missing",IFERROR(VALUE(SUBSTITUTE(SUBSTITUTE(AG6,"$",""), ".",",")),"Invalid")) -> 366.18 | AK6: =IF(AJ6=AG6,"OK","Mismatch") -> OK
A7: ='01_Raw'!A7 -> 105 | B7: =TRIM('01_Raw'!B7) -> Customer_105 | D7: =IFERROR(DATE(Q6,P6,R6),"Invalid") -> 45616 | E7: =TRIM('01_Raw'!E7) -> Tennis Racket | F7: =IF(PROPER(TRIM('01_Raw'!F7))="Electronic","Electronics",PROPER(TRIM('01_Raw'!F7))) -> Sports | I7: =TRIM('01_Raw'!I7) -> Cash on Delivery | J7: =TRIM('01_Raw'!J7) -> Cancelled | N7: =ISNUMBER('01_Raw'!D8) -> FALSE | P7: =LEFT('01_Raw'!D8, FIND("/",'01_Raw'!D8) - 1) -> 2 | Q7: =IFERROR(RIGHT('01_Raw'!D8,4),"Invalid") -> 2025 | R7: =MID('01_Raw'!D8,FIND("/",'01_Raw'!D8) + 1,FIND("/",'01_Raw'!D8,FIND("/",'01_Raw'!D8)+1)-FIND("/",'01_Raw'!D8)-1) -> 2 | S7: =IFERROR(DATE(Q7,P7,R7),"Invalid") -> 45690 | U7: =IFERROR(VALUE(SUBSTITUTE(SUBSTITUTE('01_Raw'!H8,"$",""), ".",",")),"Invalid") -> 978.63 | V7: =IFERROR(VALUE('01_Raw'!G8), "Invalid") -> Invalid | X7: =IF(ISBLANK('01_Raw'!H8),"Missing", IFERROR(VALUE(SUBSTITUTE(SUBSTITUTE('01_Raw'!H8,"$",""), ".",",")),"Invalid")) -> 978.63 | Y7: =IF(LEN(TRIM('01_Raw'!H8)) = 0, "Missing",IFERROR(VALUE(SUBSTITUTE(SUBSTITUTE('01_Raw'!H8,"$",""), ".",",")),"Invalid")) -> 978.63 | AA7: =IF(LEN(TRIM('01_Raw'!G8)) = 0, "Missing",IFERROR(VALUE(SUBSTITUTE(SUBSTITUTE('01_Raw'!G8,"$",""), ".",",")),"Invalid")) -> Missing | AC7: =COUNTIF($A$2:$A$103,A8) -> 1 | AE7: =COUNTIF(messy_ecommerce_sales_data__2[Order_ID],'01_Raw'!C8) -> 1 | AG7: =IFERROR(AA7*Y7,"Cannot Calculate") -> Cannot Calculate | AH7: =IF(AG7='01_Raw'!K8,"OK","Mismatch") -> Mismatch | AJ7: =IF(LEN(TRIM(AG7)) = 0, "Missing",IFERROR(VALUE(SUBSTITUTE(SUBSTITUTE(AG7,"$",""), ".",",")),"Invalid")) -> Invalid | AK7: =IF(AJ7=AG7,"OK","Mismatch") -> Mismatch
A8: ='01_Raw'!A8 -> 106 | B8: =TRIM('01_Raw'!B8) -> Customer_106 | D8: =IFERROR(DATE(Q7,P7,R7),"Invalid") -> 45690 | E8: =TRIM('01_Raw'!E8) -> Blender | F8: =IF(PROPER(TRIM('01_Raw'!F8))="Electronic","Electronics",PROPER(TRIM('01_Raw'!F8))) -> Home | I8: =TRIM('01_Raw'!I8) -> Bank Transfer | J8: =TRIM('01_Raw'!J8) -> Processing | N8: =ISNUMBER('01_Raw'!D9) -> FALSE | P8: =LEFT('01_Raw'!D9, FIND("/",'01_Raw'!D9) - 1) -> 1 | Q8: =IFERROR(RIGHT('01_Raw'!D9,4),"Invalid") -> 2025 | R8: =MID('01_Raw'!D9,FIND("/",'01_Raw'!D9) + 1,FIND("/",'01_Raw'!D9,FIND("/",'01_Raw'!D9)+1)-FIND("/",'01_Raw'!D9)-1) -> 3 | S8: =IFERROR(DATE(Q8,P8,R8),"Invalid") -> 45660 | U8: =IFERROR(VALUE(SUBSTITUTE(SUBSTITUTE('01_Raw'!H9,"$",""), ".",",")),"Invalid") -> 587.68 | V8: =IFERROR(VALUE('01_Raw'!G9), "Invalid") -> 5 | X8: =IF(ISBLANK('01_Raw'!H9),"Missing", IFERROR(VALUE(SUBSTITUTE(SUBSTITUTE('01_Raw'!H9,"$",""), ".",",")),"Invalid")) -> 587.68 | Y8: =IF(LEN(TRIM('01_Raw'!H9)) = 0, "Missing",IFERROR(VALUE(SUBSTITUTE(SUBSTITUTE('01_Raw'!H9,"$",""), ".",",")),"Invalid")) -> 587.68 | AA8: =IF(LEN(TRIM('01_Raw'!G9)) = 0, "Missing",IFERROR(VALUE(SUBSTITUTE(SUBSTITUTE('01_Raw'!G9,"$",""), ".",",")),"Invalid")) -> 5 | AC8: =COUNTIF($A$2:$A$103,A9) -> 1 | AE8: =COUNTIF(messy_ecommerce_sales_data__2[Order_ID],'01_Raw'!C9) -> 1 | AG8: =IFERROR(AA8*Y8,"Cannot Calculate") -> 2938.4 | AH8: =IF(AG8='01_Raw'!K9,"OK","Mismatch") -> Mismatch | AJ8: =IF(LEN(TRIM(AG8)) = 0, "Missing",IFERROR(VALUE(SUBSTITUTE(SUBSTITUTE(AG8,"$",""), ".",",")),"Invalid")) -> 2938.4 | AK8: =IF(AJ8=AG8,"OK","Mismatch") -> OK
A9: ='01_Raw'!A9 -> 107 | B9: =TRIM('01_Raw'!B9) -> Customer_107 | D9: =IFERROR(DATE(Q8,P8,R8),"Invalid") -> 45660 | E9: =TRIM('01_Raw'!E9) -> Biography | F9: =IF(PROPER(TRIM('01_Raw'!F9))="Electronic","Electronics",PROPER(TRIM('01_Raw'!F9))) -> Books | I9: =TRIM('01_Raw'!I9) -> PayPal | J9: =TRIM('01_Raw'!J9) -> Returned | N9: =ISNUMBER('01_Raw'!D10) -> FALSE | P9: =LEFT('01_Raw'!D10, FIND("/",'01_Raw'!D10) - 1) -> 10 | Q9: =IFERROR(RIGHT('01_Raw'!D10,4),"Invalid") -> 2025 | R9: =MID('01_Raw'!D10,FIND("/",'01_Raw'!D10) + 1,FIND("/",'01_Raw'!D10,FIND("/",'01_Raw'!D10)+1)-FIND("/",'01_Raw'!D10)-1) -> 23 | S9: =IFERROR(DATE(Q9,P9,R9),"Invalid") -> 45953 | U9: =IFERROR(VALUE(SUBSTITUTE(SUBSTITUTE('01_Raw'!H10,"$",""), ".",",")),"Invalid") -> 600.29 | V9: =IFERROR(VALUE('01_Raw'!G10), "Invalid") -> 1 | X9: =IF(ISBLANK('01_Raw'!H10),"Missing", IFERROR(VALUE(SUBSTITUTE(SUBSTITUTE('01_Raw'!H10,"$",""), ".",",")),"Invalid")) -> 600.29 | Y9: =IF(LEN(TRIM('01_Raw'!H10)) = 0, "Missing",IFERROR(VALUE(SUBSTITUTE(SUBSTITUTE('01_Raw'!H10,"$",""), ".",",")),"Invalid")) -> 600.29 | AA9: =IF(LEN(TRIM('01_Raw'!G10)) = 0, "Missing",IFERROR(VALUE(SUBSTITUTE(SUBSTITUTE('01_Raw'!G10,"$",""), ".",",")),"Invalid")) -> 1 | AC9: =COUNTIF($A$2:$A$103,A10) -> 1 | AE9: =COUNTIF(messy_ecommerce_sales_data__2[Order_ID],'01_Raw'!C10) -> 1 | AG9: =IFERROR(AA9*Y9,"Cannot Calculate") -> 600.29 | AH9: =IF(AG9='01_Raw'!K10,"OK","Mismatch") -> Mismatch | AJ9: =IF(LEN(TRIM(AG9)) = 0, "Missing",IFERROR(VALUE(SUBSTITUTE(SUBSTITUTE(AG9,"$",""), ".",",")),"Invalid")) -> 600.29 | AK9: =IF(AJ9=AG9,"OK","Mismatch") -> OK
A10: ='01_Raw'!A10 -> 108 | B10: =TRIM('01_Raw'!B10) -> Customer_108 | D10: =IFERROR(DATE(Q9,P9,R9),"Invalid") -> 45953 | E10: =TRIM('01_Raw'!E10) -> Science | F10: =IF(PROPER(TRIM('01_Raw'!F10))="Electronic","Electronics",PROPER(TRIM('01_Raw'!F10))) -> Books | I10: =TRIM('01_Raw'!I10) -> Cash on Delivery | J10: =TRIM('01_Raw'!J10) -> Processing | N10: =ISNUMBER('01_Raw'!D11) -> FALSE | P10: =LEFT('01_Raw'!D11, FIND("/",'01_Raw'!D11) - 1) -> 5 | Q10: =IFERROR(RIGHT('01_Raw'!D11,4),"Invalid") -> 2025 | R10: =MID('01_Raw'!D11,FIND("/",'01_Raw'!D11) + 1,FIND("/",'01_Raw'!D11,FIND("/",'01_Raw'!D11)+1)-FIND("/",'01_Raw'!D11)-1) -> 3 | S10: =IFERROR(DATE(Q10,P10,R10),"Invalid") -> 45780 | U10: =IFERROR(VALUE(SUBSTITUTE(SUBSTITUTE('01_Raw'!H11,"$",""), ".",",")),"Invalid") -> 168.34 | V10: =IFERROR(VALUE('01_Raw'!G11), "Invalid") -> 5 | X10: =IF(ISBLANK('01_Raw'!H11),"Missing", IFERROR(VALUE(SUBSTITUTE(SUBSTITUTE('01_Raw'!H11,"$",""), ".",",")),"Invalid")) -> 168.34 | Y10: =IF(LEN(TRIM('01_Raw'!H11)) = 0, "Missing",IFERROR(VALUE(SUBSTITUTE(SUBSTITUTE('01_Raw'!H11,"$",""), ".",",")),"Invalid")) -> 168.34 | AA10: =IF(LEN(TRIM('01_Raw'!G11)) = 0, "Missing",IFERROR(VALUE(SUBSTITUTE(SUBSTITUTE('01_Raw'!G11,"$",""), ".",",")),"Invalid")) -> 5 | AC10: =COUNTIF($A$2:$A$103,A11) -> 1 | AE10: =COUNTIF(messy_ecommerce_sales_data__2[Order_ID],'01_Raw'!C11) -> 1 | AG10: =IFERROR(AA10*Y10,"Cannot Calculate") -> 841.7 | AH10: =IF(AG10='01_Raw'!K11,"OK","Mismatch") -> Mismatch | AJ10: =IF(LEN(TRIM(AG10)) = 0, "Missing",IFERROR(VALUE(SUBSTITUTE(SUBSTITUTE(AG10,"$",""), ".",",")),"Invalid")) -> 841.7 | AK10: =IF(AJ10=AG10,"OK","Mismatch") -> OK
A11: ='01_Raw'!A11 -> 109 | B11: =TRIM('01_Raw'!B11) -> Customer_109 | D11: =IFERROR(DATE(Q10,P10,R10),"Invalid") -> 45780 | E11: =TRIM('01_Raw'!E11) -> Tennis Racket | F11: =IF(PROPER(TRIM('01_Raw'!F11))="Electronic","Electronics",PROPER(TRIM('01_Raw'!F11))) -> Sports | I11: =TRIM('01_Raw'!I11) -> Credit Card | J11: =TRIM('01_Raw'!J11) -> Shipped | N11: =ISNUMBER('01_Raw'!D12) -> FALSE | P11: =LEFT('01_Raw'!D12, FIND("/",'01_Raw'!D12) - 1) -> 9 | Q11: =IFERROR(RIGHT('01_Raw'!D12,4),"Invalid") -> 2025 | R11: =MID('01_Raw'!D12,FIND("/",'01_Raw'!D12) + 1,FIND("/",'01_Raw'!D12,FIND("/",'01_Raw'!D12)+1)-FIND("/",'01_Raw'!D12)-1) -> 26 | S11: =IFERROR(DATE(Q11,P11,R11),"Invalid") -> 45926 | U11: =IFERROR(VALUE(SUBSTITUTE(SUBSTITUTE('01_Raw'!H12,"$",""), ".",",")),"Invalid") -> Invalid | V11: =IFERROR(VALUE('01_Raw'!G12), "Invalid") -> 5 | X11: =IF(ISBLANK('01_Raw'!H12),"Missing", IFERROR(VALUE(SUBSTITUTE(SUBSTITUTE('01_Raw'!H12,"$",""), ".",",")),"Invalid")) -> Invalid | Y11: =IF(LEN(TRIM('01_Raw'!H12)) = 0, "Missing",IFERROR(VALUE(SUBSTITUTE(SUBSTITUTE('01_Raw'!H12,"$",""), ".",",")),"Invalid")) -> Invalid | AA11: =IF(LEN(TRIM('01_Raw'!G12)) = 0, "Missing",IFERROR(VALUE(SUBSTITUTE(SUBSTITUTE('01_Raw'!G12,"$",""), ".",",")),"Invalid")) -> 5 | AC11: =COUNTIF($A$2:$A$103,A12) -> 1 | AE11: =COUNTIF(messy_ecommerce_sales_data__2[Order_ID],'01_Raw'!C12) -> 1 | AG11: =IFERROR(AA11*Y11,"Cannot Calculate") -> Cannot Calculate | AH11: =IF(AG11='01_Raw'!K12,"OK","Mismatch") -> Mismatch | AJ11: =IF(LEN(TRIM(AG11)) = 0, "Missing",IFERROR(VALUE(SUBSTITUTE(SUBSTITUTE(AG11,"$",""), ".",",")),"Invalid")) -> Invalid | AK11: =IF(AJ11=AG11,"OK","Mismatch") -> Mismatch
A12: ='01_Raw'!A12 -> 110 | B12: =TRIM('01_Raw'!B12) -> Customer_110 | D12: =IFERROR(DATE(Q11,P11,R11),"Invalid") -> 45926 | E12: =TRIM('01_Raw'!E12) -> Basketball | F12: =IF(PROPER(TRIM('01_Raw'!F12))="Electronic","Electronics",PROPER(TRIM('01_Raw'!F12))) -> Sports | I12: =TRIM('01_Raw'!I12) -> Cash on Delivery | J12: =TRIM('01_Raw'!J12) -> Cancelled | N12: =ISNUMBER('01_Raw'!D13) -> FALSE | P12: =LEFT('01_Raw'!D13, FIND("/",'01_Raw'!D13) - 1) -> 10 | Q12: =IFERROR(RIGHT('01_Raw'!D13,4),"Invalid") -> 2025 | R12: =MID('01_Raw'!D13,FIND("/",'01_Raw'!D13) + 1,FIND("/",'01_Raw'!D13,FIND("/",'01_Raw'!D13)+1)-FIND("/",'01_Raw'!D13)-1) -> 22 | S12: =IFERROR(DATE(Q12,P12,R12),"Invalid") -> 45952 | U12: =IFERROR(VALUE(SUBSTITUTE(SUBSTITUTE('01_Raw'!H13,"$",""), ".",",")),"Invalid") -> 865.77 | V12: =IFERROR(VALUE('01_Raw'!G13), "Invalid") -> 2 | X12: =IF(ISBLANK('01_Raw'!H13),"Missing", IFERROR(VALUE(SUBSTITUTE(SUBSTITUTE('01_Raw'!H13,"$",""), ".",",")),"Invalid")) -> 865.77 | Y12: =IF(LEN(TRIM('01_Raw'!H13)) = 0, "Missing",IFERROR(VALUE(SUBSTITUTE(SUBSTITUTE('01_Raw'!H13,"$",""), ".",",")),"Invalid")) -> 865.77 | AA12: =IF(LEN(TRIM('01_Raw'!G13)) = 0, "Missing",IFERROR(VALUE(SUBSTITUTE(SUBSTITUTE('01_Raw'!G13,"$",""), ".",",")),"Invalid")) -> 2 | AC12: =COUNTIF($A$2:$A$103,A13) -> 1 | AE12: =COUNTIF(messy_ecommerce_sales_data__2[Order_ID],'01_Raw'!C13) -> 1 | AG12: =IFERROR(AA12*Y12,"Cannot Calculate") -> 1731.54 | AH12: =IF(AG12='01_Raw'!K13,"OK","Mismatch") -> Mismatch | AJ12: =IF(LEN(TRIM(AG12)) = 0, "Missing",IFERROR(VALUE(SUBSTITUTE(SUBSTITUTE(AG12,"$",""), ".",",")),"Invalid")) -> 1731.54 | AK12: =IF(AJ12=AG12,"OK","Mismatch") -> OK
A13: ='01_Raw'!A13 -> 111 | B13: =TRIM('01_Raw'!B13) -> Customer_111 | D13: =IFERROR(DATE(Q12,P12,R12),"Invalid") -> 45952 | E13: =TRIM('01_Raw'!E13) -> Comics | F13: =IF(PROPER(TRIM('01_Raw'!F13))="Electronic","Electronics",PROPER(TRIM('01_Raw'!F13))) -> Books | I13: =TRIM('01_Raw'!I13) -> Credit Card | J13: =TRIM('01_Raw'!J13) -> Returned | N13: =ISNUMBER('01_Raw'!D14) -> FALSE | P13: =LEFT('01_Raw'!D14, FIND("/",'01_Raw'!D14) - 1) -> 3 | Q13: =IFERROR(RIGHT('01_Raw'!D14,4),"Invalid") -> 2025 | R13: =MID('01_Raw'!D14,FIND("/",'01_Raw'!D14) + 1,FIND("/",'01_Raw'!D14,FIND("/",'01_Raw'!D14)+1)-FIND("/",'01_Raw'!D14)-1) -> 2 | S13: =IFERROR(DATE(Q13,P13,R13),"Invalid") -> 45718 | U13: =IFERROR(VALUE(SUBSTITUTE(SUBSTITUTE('01_Raw'!H14,"$",""), ".",",")),"Invalid") -> 752.13 | V13: =IFERROR(VALUE('01_Raw'!G14), "Invalid") -> 4 | X13: =IF(ISBLANK('01_Raw'!H14),"Missing", IFERROR(VALUE(SUBSTITUTE(SUBSTITUTE('01_Raw'!H14,"$",""), ".",",")),"Invalid")) -> 752.13 | Y13: =IF(LEN(TRIM('01_Raw'!H14)) = 0, "Missing",IFERROR(VALUE(SUBSTITUTE(SUBSTITUTE('01_Raw'!H14,"$",""), ".",",")),"Invalid")) -> 752.13 | AA13: =IF(LEN(TRIM('01_Raw'!G14)) = 0, "Missing",IFERROR(VALUE(SUBSTITUTE(SUBSTITUTE('01_Raw'!G14,"$",""), ".",",")),"Invalid")) -> 4 | AC13: =COUNTIF($A$2:$A$103,A14) -> 1 | AE13: =COUNTIF(messy_ecommerce_sales_data__2[Order_ID],'01_Raw'!C14) -> 1 | AG13: =IFERROR(AA13*Y13,"Cannot Calculate") -> 3008.52 | AH13: =IF(AG13='01_Raw'!K14,"OK","Mismatch") -> Mismatch | AJ13: =IF(LEN(TRIM(AG13)) = 0, "Missing",IFERROR(VALUE(SUBSTITUTE(SUBSTITUTE(AG13,"$",""), ".",",")),"Invalid")) -> 3008.52 | AK13: =IF(AJ13=AG13,"OK","Mismatch") -> OK
... A42: ='01_Raw'!A42 -> 140 | B42: =TRIM('01_Raw'!B42) -> Customer_140 | D42: =IFERROR(DATE(Q41,P41,R41),"Invalid") -> 45714 | E42: =TRIM('01_Raw'!E42) -> Fiction | F42: =IF(PROPER(TRIM('01_Raw'!F42))="Electronic","Electronics",PROPER(TRIM('01_Raw'!F42))) -> Books | I42: =TRIM('01_Raw'!I42) -> Credit Card | J42: =TRIM('01_Raw'!J42) -> Returned | N42: =ISNUMBER('01_Raw'!D43) -> FALSE | P42: =LEFT('01_Raw'!D43, FIND("/",'01_Raw'!D43) - 1) -> 2 | Q42: =IFERROR(RIGHT('01_Raw'!D43,4),"Invalid") -> 2025 | R42: =MID('01_Raw'!D43,FIND("/",'01_Raw'!D43) + 1,FIND("/",'01_Raw'!D43,FIND("/",'01_Raw'!D43)+1)-FIND("/",'01_Raw'!D43)-1) -> 13 | S42: =IFERROR(DATE(Q42,P42,R42),"Invalid") -> 45701 | U42: =IFERROR(VALUE(SUBSTITUTE(SUBSTITUTE('01_Raw'!H43,"$",""), ".",",")),"Invalid") -> 546.04 | V42: =IFERROR(VALUE('01_Raw'!G43), "Invalid") -> 3 | X42: =IF(ISBLANK('01_Raw'!H43),"Missing", IFERROR(VALUE(SUBSTITUTE(SUBSTITUTE('01_Raw'!H43,"$",""), ".",",")),"Invalid")) -> 546.04 | Y42: =IF(LEN(TRIM('01_Raw'!H43)) = 0, "Missing",IFERROR(VALUE(SUBSTITUTE(SUBSTITUTE('01_Raw'!H43,"$",""), ".",",")),"Invalid")) -> 546.04 | AA42: =IF(LEN(TRIM('01_Raw'!G43)) = 0, "Missing",IFERROR(VALUE(SUBSTITUTE(SUBSTITUTE('01_Raw'!G43,"$",""), ".",",")),"Invalid")) -> 3 | AC42: =COUNTIF($A$2:$A$103,A43) -> 1 | AE42: =COUNTIF(messy_ecommerce_sales_data__2[Order_ID],'01_Raw'!C43) -> 1 | AG42: =IFERROR(AA42*Y42,"Cannot Calculate") -> 1638.12 | AH42: =IF(AG42='01_Raw'!K43,"OK","Mismatch") -> Mismatch | AJ42: =IF(LEN(TRIM(AG42)) = 0, "Missing",IFERROR(VALUE(SUBSTITUTE(SUBSTITUTE(AG42,"$",""), ".",",")),"Invalid")) -> 1638.12 | AK42: =IF(AJ42=AG42,"OK","Mismatch") -> OK
A43: ='01_Raw'!A43 -> 141 | B43: =TRIM('01_Raw'!B43) -> Customer_141 | D43: =IFERROR(DATE(Q42,P42,R42),"Invalid") -> 45701 | E43: =TRIM('01_Raw'!E43) -> Fiction | F43: =IF(PROPER(TRIM('01_Raw'!F43))="Electronic","Electronics",PROPER(TRIM('01_Raw'!F43))) -> Books | I43: =TRIM('01_Raw'!I43) -> Cash on Delivery | J43: =TRIM('01_Raw'!J43) -> Returned | N43: =ISNUMBER('01_Raw'!D44) -> FALSE | P43: =LEFT('01_Raw'!D44, FIND("/",'01_Raw'!D44) - 1) -> 10 | Q43: =IFERROR(RIGHT('01_Raw'!D44,4),"Invalid") -> 2025 | R43: =MID('01_Raw'!D44,FIND("/",'01_Raw'!D44) + 1,FIND("/",'01_Raw'!D44,FIND("/",'01_Raw'!D44)+1)-FIND("/",'01_Raw'!D44)-1) -> 30 | S43: =IFERROR(DATE(Q43,P43,R43),"Invalid") -> 45960 | U43: =IFERROR(VALUE(SUBSTITUTE(SUBSTITUTE('01_Raw'!H44,"$",""), ".",",")),"Invalid") -> 645.26 | V43: =IFERROR(VALUE('01_Raw'!G44), "Invalid") -> 5 | X43: =IF(ISBLANK('01_Raw'!H44),"Missing", IFERROR(VALUE(SUBSTITUTE(SUBSTITUTE('01_Raw'!H44,"$",""), ".",",")),"Invalid")) -> 645.26 | Y43: =IF(LEN(TRIM('01_Raw'!H44)) = 0, "Missing",IFERROR(VALUE(SUBSTITUTE(SUBSTITUTE('01_Raw'!H44,"$",""), ".",",")),"Invalid")) -> 645.26 | AA43: =IF(LEN(TRIM('01_Raw'!G44)) = 0, "Missing",IFERROR(VALUE(SUBSTITUTE(SUBSTITUTE('01_Raw'!G44,"$",""), ".",",")),"Invalid")) -> 5 | AC43: =COUNTIF($A$2:$A$103,#REF!) -> 0 | AE43: =COUNTIF(messy_ecommerce_sales_data__2[Order_ID],'01_Raw'!C44) -> 2 | AG43: =IFERROR(AA43*Y43,"Cannot Calculate") -> 3226.3 | AH43: =IF(AG43='01_Raw'!K44,"OK","Mismatch") -> Mismatch | AJ43: =IF(LEN(TRIM(AG43)) = 0, "Missing",IFERROR(VALUE(SUBSTITUTE(SUBSTITUTE(AG43,"$",""), ".",",")),"Invalid")) -> 3226.3 | AK43: =IF(AJ43=AG43,"OK","Mismatch") -> OK
A44: ='01_Raw'!A45 -> 143 | B44: =TRIM('01_Raw'!B45) -> Customer_143 | D44: =IFERROR(DATE(Q43,P43,R43),"Invalid") -> 45960 | E44: =TRIM('01_Raw'!E45) -> T-shirt | F44: =IF(PROPER(TRIM('01_Raw'!F45))="Electronic","Electronics",PROPER(TRIM('01_Raw'!F45))) -> Clothing | I44: =TRIM('01_Raw'!I45) -> Bank Transfer | J44: =TRIM('01_Raw'!J45) -> Cancelled | N44: =ISNUMBER('01_Raw'!D46) -> FALSE | P44: =LEFT('01_Raw'!D46, FIND("/",'01_Raw'!D46) - 1) -> 1 | Q44: =IFERROR(RIGHT('01_Raw'!D46,4),"Invalid") -> 2025 | R44: =MID('01_Raw'!D46,FIND("/",'01_Raw'!D46) + 1,FIND("/",'01_Raw'!D46,FIND("/",'01_Raw'!D46)+1)-FIND("/",'01_Raw'!D46)-1) -> 27 | S44: =IFERROR(DATE(Q44,P44,R44),"Invalid") -> 45684 | U44: =IFERROR(VALUE(SUBSTITUTE(SUBSTITUTE('01_Raw'!H46,"$",""), ".",",")),"Invalid") -> 849.07 | V44: =IFERROR(VALUE('01_Raw'!G46), "Invalid") -> 5 | X44: =IF(ISBLANK('01_Raw'!H46),"Missing", IFERROR(VALUE(SUBSTITUTE(SUBSTITUTE('01_Raw'!H46,"$",""), ".",",")),"Invalid")) -> 849.07 | Y44: =IF(LEN(TRIM('01_Raw'!H46)) = 0, "Missing",IFERROR(VALUE(SUBSTITUTE(SUBSTITUTE('01_Raw'!H46,"$",""), ".",",")),"Invalid")) -> 849.07 | AA44: =IF(LEN(TRIM('01_Raw'!G46)) = 0, "Missing",IFERROR(VALUE(SUBSTITUTE(SUBSTITUTE('01_Raw'!G46,"$",""), ".",",")),"Invalid")) -> 5 | AC44: =COUNTIF($A$2:$A$103,A45) -> 1 | AE44: =COUNTIF(messy_ecommerce_sales_data__2[Order_ID],'01_Raw'!C46) -> 1 | AG44: =IFERROR(AA44*Y44,"Cannot Calculate") -> 4245.35 | AH44: =IF(AG44='01_Raw'!K45,"OK","Mismatch") -> Mismatch | AJ44: =IF(LEN(TRIM(AG44)) = 0, "Missing",IFERROR(VALUE(SUBSTITUTE(SUBSTITUTE(AG44,"$",""), ".",",")),"Invalid")) -> 4245.35 | AK44: =IF(AJ44=AG44,"OK","Mismatch") -> OK
A45: ='01_Raw'!A46 -> 144 | B45: =TRIM('01_Raw'!B46) -> Customer_144 | D45: =IFERROR(DATE(Q44,P44,R44),"Invalid") -> 45684 | E45: =TRIM('01_Raw'!E46) -> Football | F45: =IF(PROPER(TRIM('01_Raw'!F46))="Electronic","Electronics",PROPER(TRIM('01_Raw'!F46))) -> Sports | I45: =TRIM('01_Raw'!I46) -> Bank Transfer | J45: =TRIM('01_Raw'!J46) -> Processing | N45: =ISNUMBER('01_Raw'!D47) -> FALSE | P45: =LEFT('01_Raw'!D47, FIND("/",'01_Raw'!D47) - 1) -> 5 | Q45: =IFERROR(RIGHT('01_Raw'!D47,4),"Invalid") -> 2023 | R45: =MID('01_Raw'!D47,FIND("/",'01_Raw'!D47) + 1,FIND("/",'01_Raw'!D47,FIND("/",'01_Raw'!D47)+1)-FIND("/",'01_Raw'!D47)-1) -> 1 | S45: =IFERROR(DATE(Q45,P45,R45),"Invalid") -> 45047 | U45: =IFERROR(VALUE(SUBSTITUTE(SUBSTITUTE('01_Raw'!H47,"$",""), ".",",")),"Invalid") -> 860.99 | V45: =IFERROR(VALUE('01_Raw'!G47), "Invalid") -> 2 | X45: =IF(ISBLANK('01_Raw'!H47),"Missing", IFERROR(VALUE(SUBSTITUTE(SUBSTITUTE('01_Raw'!H47,"$",""), ".",",")),"Invalid")) -> 860.99 | Y45: =IF(LEN(TRIM('01_Raw'!H47)) = 0, "Missing",IFERROR(VALUE(SUBSTITUTE(SUBSTITUTE('01_Raw'!H47,"$",""), ".",",")),"Invalid")) -> 860.99 | AA45: =IF(LEN(TRIM('01_Raw'!G47)) = 0, "Missing",IFERROR(VALUE(SUBSTITUTE(SUBSTITUTE('01_Raw'!G47,"$",""), ".",",")),"Invalid")) -> 2 | AC45: =COUNTIF($A$2:$A$103,A46) -> 1 | AE45: =COUNTIF(messy_ecommerce_sales_data__2[Order_ID],'01_Raw'!C47) -> 1 | AG45: =IFERROR(AA45*Y45,"Cannot Calculate") -> 1721.98 | AH45: =IF(AG45='01_Raw'!K46,"OK","Mismatch") -> Mismatch | AJ45: =IF(LEN(TRIM(AG45)) = 0, "Missing",IFERROR(VALUE(SUBSTITUTE(SUBSTITUTE(AG45,"$",""), ".",",")),"Invalid")) -> 1721.98 | AK45: =IF(AJ45=AG45,"OK","Mismatch") -> OK
A46: ='01_Raw'!A47 -> 145 | B46: =TRIM('01_Raw'!B47) -> Customer_145 | D46: =IFERROR(DATE(Q45,P45,R45),"Invalid") -> 45047 | E46: =TRIM('01_Raw'!E47) -> Laptop | F46: =IF(PROPER(TRIM('01_Raw'!F47))="Electronic","Electronics",PROPER(TRIM('01_Raw'!F47))) -> Electronics | I46: =TRIM('01_Raw'!I47) -> Bank Transfer | J46: =TRIM('01_Raw'!J47) -> Returned | N46: =ISNUMBER('01_Raw'!D48) -> FALSE | P46: =LEFT('01_Raw'!D48, FIND("/",'01_Raw'!D48) - 1) -> 7 | Q46: =IFERROR(RIGHT('01_Raw'!D48,4),"Invalid") -> 2025 | R46: =MID('01_Raw'!D48,FIND("/",'01_Raw'!D48) + 1,FIND("/",'01_Raw'!D48,FIND("/",'01_Raw'!D48)+1)-FIND("/",'01_Raw'!D48)-1) -> 9 | S46: =IFERROR(DATE(Q46,P46,R46),"Invalid") -> 45847 | U46: =IFERROR(VALUE(SUBSTITUTE(SUBSTITUTE('01_Raw'!H48,"$",""), ".",",")),"Invalid") -> 705.42 | V46: =IFERROR(VALUE('01_Raw'!G48), "Invalid") -> 2 | X46: =IF(ISBLANK('01_Raw'!H48),"Missing", IFERROR(VALUE(SUBSTITUTE(SUBSTITUTE('01_Raw'!H48,"$",""), ".",",")),"Invalid")) -> 705.42 | Y46: =IF(LEN(TRIM('01_Raw'!H48)) = 0, "Missing",IFERROR(VALUE(SUBSTITUTE(SUBSTITUTE('01_Raw'!H48,"$",""), ".",",")),"Invalid")) -> 705.42 | AA46: =IF(LEN(TRIM('01_Raw'!G48)) = 0, "Missing",IFERROR(VALUE(SUBSTITUTE(SUBSTITUTE('01_Raw'!G48,"$",""), ".",",")),"Invalid")) -> 2 | AC46: =COUNTIF($A$2:$A$103,A47) -> 2 | AE46: =COUNTIF(messy_ecommerce_sales_data__2[Order_ID],'01_Raw'!C48) -> 2 | AG46: =IFERROR(AA46*Y46,"Cannot Calculate") -> 1410.84 | AH46: =IF(AG46='01_Raw'!K47,"OK","Mismatch") -> Mismatch | AJ46: =IF(LEN(TRIM(AG46)) = 0, "Missing",IFERROR(VALUE(SUBSTITUTE(SUBSTITUTE(AG46,"$",""), ".",",")),"Invalid")) -> 1410.84 | AK46: =IF(AJ46=AG46,"OK","Mismatch") -> OK
A47: ='01_Raw'!A48 -> 146 | B47: =TRIM('01_Raw'!B48) -> Customer_146 | D47: =IFERROR(DATE(Q46,P46,R46),"Invalid") -> 45847 | E47: =TRIM('01_Raw'!E48) -> Basketball | F47: =IF(PROPER(TRIM('01_Raw'!F48))="Electronic","Electronics",PROPER(TRIM('01_Raw'!F48))) -> Electronics | I47: =TRIM('01_Raw'!I48) -> Bank Transfer | J47: =TRIM('01_Raw'!J48) -> Processing | N47: =ISNUMBER('01_Raw'!D49) -> FALSE | P47: =LEFT('01_Raw'!D49, FIND("/",'01_Raw'!D49) - 1) -> 5 | Q47: =IFERROR(RIGHT('01_Raw'!D49,4),"Invalid") -> 2025 | R47: =MID('01_Raw'!D49,FIND("/",'01_Raw'!D49) + 1,FIND("/",'01_Raw'!D49,FIND("/",'01_Raw'!D49)+1)-FIND("/",'01_Raw'!D49)-1) -> 1 | S47: =IFERROR(DATE(Q47,P47,R47),"Invalid") -> 45778 | U47: =IFERROR(VALUE(SUBSTITUTE(SUBSTITUTE('01_Raw'!H49,"$",""), ".",",")),"Invalid") -> 596.15 | V47: =IFERROR(VALUE('01_Raw'!G49), "Invalid") -> 4 | X47: =IF(ISBLANK('01_Raw'!H49),"Missing", IFERROR(VALUE(SUBSTITUTE(SUBSTITUTE('01_Raw'!H49,"$",""), ".",",")),"Invalid")) -> 596.15 | Y47: =IF(LEN(TRIM('01_Raw'!H49)) = 0, "Missing",IFERROR(VALUE(SUBSTITUTE(SUBSTITUTE('01_Raw'!H49,"$",""), ".",",")),"Invalid")) -> 596.15 | AA47: =IF(LEN(TRIM('01_Raw'!G49)) = 0, "Missing",IFERROR(VALUE(SUBSTITUTE(SUBSTITUTE('01_Raw'!G49,"$",""), ".",",")),"Invalid")) -> 4 | AC47: =COUNTIF($A$2:$A$103,A48) -> 1 | AE47: =COUNTIF(messy_ecommerce_sales_data__2[Order_ID],'01_Raw'!C49) -> 1 | AG47: =IFERROR(AA47*Y47,"Cannot Calculate") -> 2384.6 | AH47: =IF(AG47='01_Raw'!K48,"OK","Mismatch") -> Mismatch | AJ47: =IF(LEN(TRIM(AG47)) = 0, "Missing",IFERROR(VALUE(SUBSTITUTE(SUBSTITUTE(AG47,"$",""), ".",",")),"Invalid")) -> 2384.6 | AK47: =IF(AJ47=AG47,"OK","Mismatch") -> OK
A48: ='01_Raw'!A49 -> 147 | B48: =TRIM('01_Raw'!B49) -> Customer_147 | D48: =IFERROR(DATE(Q47,P47,R47),"Invalid") -> 45778 | E48: =TRIM('01_Raw'!E49) -> Jacket | F48: =IF(PROPER(TRIM('01_Raw'!F49))="Electronic","Electronics",PROPER(TRIM('01_Raw'!F49))) -> Clothing | I48: =TRIM('01_Raw'!I49) -> Cash on Delivery | J48: =TRIM('01_Raw'!J49) -> Shipped | N48: =ISNUMBER('01_Raw'!D50) -> FALSE | P48: =LEFT('01_Raw'!D50, FIND("/",'01_Raw'!D50) - 1) -> 3 | Q48: =IFERROR(RIGHT('01_Raw'!D50,4),"Invalid") -> 2025 | R48: =MID('01_Raw'!D50,FIND("/",'01_Raw'!D50) + 1,FIND("/",'01_Raw'!D50,FIND("/",'01_Raw'!D50)+1)-FIND("/",'01_Raw'!D50)-1) -> 13 | S48: =IFERROR(DATE(Q48,P48,R48),"Invalid") -> 45729 | U48: =IFERROR(VALUE(SUBSTITUTE(SUBSTITUTE('01_Raw'!H50,"$",""), ".",",")),"Invalid") -> 660.98 | V48: =IFERROR(VALUE('01_Raw'!G50), "Invalid") -> 1 | X48: =IF(ISBLANK('01_Raw'!H50),"Missing", IFERROR(VALUE(SUBSTITUTE(SUBSTITUTE('01_Raw'!H50,"$",""), ".",",")),"Invalid")) -> 660.98 | Y48: =IF(LEN(TRIM('01_Raw'!H50)) = 0, "Missing",IFERROR(VALUE(SUBSTITUTE(SUBSTITUTE('01_Raw'!H50,"$",""), ".",",")),"Invalid")) -> 660.98 | AA48: =IF(LEN(TRIM('01_Raw'!G50)) = 0, "Missing",IFERROR(VALUE(SUBSTITUTE(SUBSTITUTE('01_Raw'!G50,"$",""), ".",",")),"Invalid")) -> 1 | AC48: =COUNTIF($A$2:$A$103,A49) -> 1 | AE48: =COUNTIF(messy_ecommerce_sales_data__2[Order_ID],'01_Raw'!C50) -> 1 | AG48: =IFERROR(AA48*Y48,"Cannot Calculate") -> 660.98 | AH48: =IF(AG48='01_Raw'!K49,"OK","Mismatch") -> Mismatch | AJ48: =IF(LEN(TRIM(AG48)) = 0, "Missing",IFERROR(VALUE(SUBSTITUTE(SUBSTITUTE(AG48,"$",""), ".",",")),"Invalid")) -> 660.98 | AK48: =IF(AJ48=AG48,"OK","Mismatch") -> OK
A49: ='01_Raw'!A50 -> 148 | B49: =TRIM('01_Raw'!B50) -> Customer_148 | D49: =IFERROR(DATE(Q48,P48,R48),"Invalid") -> 45729 | E49: =TRIM('01_Raw'!E50) -> Tennis Racket | F49: =IF(PROPER(TRIM('01_Raw'!F50))="Electronic","Electronics",PROPER(TRIM('01_Raw'!F50))) -> Sports | I49: =TRIM('01_Raw'!I50) -> Cash on Delivery | J49: =TRIM('01_Raw'!J50) -> Returned | N49: =ISNUMBER('01_Raw'!D51) -> FALSE | P49: =LEFT('01_Raw'!D51, FIND("/",'01_Raw'!D51) - 1) -> 6 | Q49: =IFERROR(RIGHT('01_Raw'!D51,4),"Invalid") -> 2025 | R49: =MID('01_Raw'!D51,FIND("/",'01_Raw'!D51) + 1,FIND("/",'01_Raw'!D51,FIND("/",'01_Raw'!D51)+1)-FIND("/",'01_Raw'!D51)-1) -> 29 | S49: =IFERROR(DATE(Q49,P49,R49),"Invalid") -> 45837 | U49: =IFERROR(VALUE(SUBSTITUTE(SUBSTITUTE('01_Raw'!H51,"$",""), ".",",")),"Invalid") -> 896.38 | V49: =IFERROR(VALUE('01_Raw'!G51), "Invalid") -> 5 | X49: =IF(ISBLANK('01_Raw'!H51),"Missing", IFERROR(VALUE(SUBSTITUTE(SUBSTITUTE('01_Raw'!H51,"$",""), ".",",")),"Invalid")) -> 896.38 | Y49: =IF(LEN(TRIM('01_Raw'!H51)) = 0, "Missing",IFERROR(VALUE(SUBSTITUTE(SUBSTITUTE('01_Raw'!H51,"$",""), ".",",")),"Invalid")) -> 896.38 | AA49: =IF(LEN(TRIM('01_Raw'!G51)) = 0, "Missing",IFERROR(VALUE(SUBSTITUTE(SUBSTITUTE('01_Raw'!G51,"$",""), ".",",")),"Invalid")) -> 5 | AC49: =COUNTIF($A$2:$A$103,A50) -> 1 | AE49: =COUNTIF(messy_ecommerce_sales_data__2[Order_ID],'01_Raw'!C51) -> 1 | AG49: =IFERROR(AA49*Y49,"Cannot Calculate") -> 4481.9 | AH49: =IF(AG49='01_Raw'!K50,"OK","Mismatch") -> Mismatch | AJ49: =IF(LEN(TRIM(AG49)) = 0, "Missing",IFERROR(VALUE(SUBSTITUTE(SUBSTITUTE(AG49,"$",""), ".",",")),"Invalid")) -> 4481.9 | AK49: =IF(AJ49=AG49,"OK","Mismatch") -> OK
A50: ='01_Raw'!A51 -> 149 | B50: =TRIM('01_Raw'!B51) -> Customer_149 | D50: =IFERROR(DATE(Q49,P49,R49),"Invalid") -> 45837 | E50: =TRIM('01_Raw'!E51) -> Comics | F50: =IF(PROPER(TRIM('01_Raw'!F51))="Electronic","Electronics",PROPER(TRIM('01_Raw'!F51))) -> Books | I50: =TRIM('01_Raw'!I51) -> Bank Transfer | J50: =TRIM('01_Raw'!J51) -> Cancelled | N50: =ISNUMBER('01_Raw'!D52) -> FALSE | P50: =LEFT('01_Raw'!D52, FIND("/",'01_Raw'!D52) - 1) -> 11 | Q50: =IFERROR(RIGHT('01_Raw'!D52,4),"Invalid") -> 2024 | R50: =MID('01_Raw'!D52,FIND("/",'01_Raw'!D52) + 1,FIND("/",'01_Raw'!D52,FIND("/",'01_Raw'!D52)+1)-FIND("/",'01_Raw'!D52)-1) -> 27 | S50: =IFERROR(DATE(Q50,P50,R50),"Invalid") -> 45623 | U50: =IFERROR(VALUE(SUBSTITUTE(SUBSTITUTE('01_Raw'!H52,"$",""), ".",",")),"Invalid") -> 206.19 | V50: =IFERROR(VALUE('01_Raw'!G52), "Invalid") -> 1 | X50: =IF(ISBLANK('01_Raw'!H52),"Missing", IFERROR(VALUE(SUBSTITUTE(SUBSTITUTE('01_Raw'!H52,"$",""), ".",",")),"Invalid")) -> 206.19 | Y50: =IF(LEN(TRIM('01_Raw'!H52)) = 0, "Missing",IFERROR(VALUE(SUBSTITUTE(SUBSTITUTE('01_Raw'!H52,"$",""), ".",",")),"Invalid")) -> 206.19 | AA50: =IF(LEN(TRIM('01_Raw'!G52)) = 0, "Missing",IFERROR(VALUE(SUBSTITUTE(SUBSTITUTE('01_Raw'!G52,"$",""), ".",",")),"Invalid")) -> 1 | AC50: =COUNTIF($A$2:$A$103,A51) -> 1 | AE50: =COUNTIF(messy_ecommerce_sales_data__2[Order_ID],'01_Raw'!C52) -> 1 | AG50: =IFERROR(AA50*Y50,"Cannot Calculate") -> 206.19 | AH50: =IF(AG50='01_Raw'!K51,"OK","Mismatch") -> Mismatch | AJ50: =IF(LEN(TRIM(AG50)) = 0, "Missing",IFERROR(VALUE(SUBSTITUTE(SUBSTITUTE(AG50,"$",""), ".",",")),"Invalid")) -> 206.19 | AK50: =IF(AJ50=AG50,"OK","Mismatch") -> OK
A51: ='01_Raw'!A52 -> 150 | B51: =TRIM('01_Raw'!B52) -> Customer_150 | D51: =IFERROR(DATE(Q50,P50,R50),"Invalid") -> 45623 | E51: =TRIM('01_Raw'!E52) -> Yoga Mat | F51: =IF(PROPER(TRIM('01_Raw'!F52))="Electronic","Electronics",PROPER(TRIM('01_Raw'!F52))) -> Sports | I51: =TRIM('01_Raw'!I52) -> Credit Card | J51: =TRIM('01_Raw'!J52) -> Returned | N51: =ISNUMBER('01_Raw'!D53) -> FALSE | P51: =LEFT('01_Raw'!D53, FIND("/",'01_Raw'!D53) - 1) -> 7 | Q51: =IFERROR(RIGHT('01_Raw'!D53,4),"Invalid") -> 2025 | R51: =MID('01_Raw'!D53,FIND("/",'01_Raw'!D53) + 1,FIND("/",'01_Raw'!D53,FIND("/",'01_Raw'!D53)+1)-FIND("/",'01_Raw'!D53)-1) -> 1 | S51: =IFERROR(DATE(Q51,P51,R51),"Invalid") -> 45839 | U51: =IFERROR(VALUE(SUBSTITUTE(SUBSTITUTE('01_Raw'!H53,"$",""), ".",",")),"Invalid") -> 457.16 | V51: =IFERROR(VALUE('01_Raw'!G53), "Invalid") -> 2 | X51: =IF(ISBLANK('01_Raw'!H53),"Missing", IFERROR(VALUE(SUBSTITUTE(SUBSTITUTE('01_Raw'!H53,"$",""), ".",",")),"Invalid")) -> 457.16 | Y51: =IF(LEN(TRIM('01_Raw'!H53)) = 0, "Missing",IFERROR(VALUE(SUBSTITUTE(SUBSTITUTE('01_Raw'!H53,"$",""), ".",",")),"Invalid")) -> 457.16 | AA51: =IF(LEN(TRIM('01_Raw'!G53)) = 0, "Missing",IFERROR(VALUE(SUBSTITUTE(SUBSTITUTE('01_Raw'!G53,"$",""), ".",",")),"Invalid")) -> 2 | AC51: =COUNTIF($A$2:$A$103,A52) -> 1 | AE51: =COUNTIF(messy_ecommerce_sales_data__2[Order_ID],'01_Raw'!C53) -> 1 | AG51: =IFERROR(AA51*Y51,"Cannot Calculate") -> 914.32 | AH51: =IF(AG51='01_Raw'!K52,"OK","Mismatch") -> Mismatch | AJ51: =IF(LEN(TRIM(AG51)) = 0, "Missing",IFERROR(VALUE(SUBSTITUTE(SUBSTITUTE(AG51,"$",""), ".",",")),"Invalid")) -> 914.32 | AK51: =IF(AJ51=AG51,"OK","Mismatch") -> OK
A52: ='01_Raw'!A53 -> 151 | B52: =TRIM('01_Raw'!B53) -> Customer_151 | D52: =IFERROR(DATE(Q51,P51,R51),"Invalid") -> 45839 | E52: =TRIM('01_Raw'!E53) -> Comics | F52: =IF(PROPER(TRIM('01_Raw'!F53))="Electronic","Electronics",PROPER(TRIM('01_Raw'!F53))) -> Books | I52: =TRIM('01_Raw'!I53) -> PayPal | J52: =TRIM('01_Raw'!J53) -> Processing | N52: =ISNUMBER('01_Raw'!D54) -> FALSE | P52: =LEFT('01_Raw'!D54, FIND("/",'01_Raw'!D54) - 1) -> 9 | Q52: =IFERROR(RIGHT('01_Raw'!D54,4),"Invalid") -> 2025 | R52: =MID('01_Raw'!D54,FIND("/",'01_Raw'!D54) + 1,FIND("/",'01_Raw'!D54,FIND("/",'01_Raw'!D54)+1)-FIND("/",'01_Raw'!D54)-1) -> 22 | S52: =IFERROR(DATE(Q52,P52,R52),"Invalid") -> 45922 | U52: =IFERROR(VALUE(SUBSTITUTE(SUBSTITUTE('01_Raw'!H54,"$",""), ".",",")),"Invalid") -> 233.11 | V52: =IFERROR(VALUE('01_Raw'!G54), "Invalid") -> 3 | X52: =IF(ISBLANK('01_Raw'!H54),"Missing", IFERROR(VALUE(SUBSTITUTE(SUBSTITUTE('01_Raw'!H54,"$",""), ".",",")),"Invalid")) -> 233.11 | Y52: =IF(LEN(TRIM('01_Raw'!H54)) = 0, "Missing",IFERROR(VALUE(SUBSTITUTE(SUBSTITUTE('01_Raw'!H54,"$",""), ".",",")),"Invalid")) -> 233.11 | AA52: =IF(LEN(TRIM('01_Raw'!G54)) = 0, "Missing",IFERROR(VALUE(SUBSTITUTE(SUBSTITUTE('01_Raw'!G54,"$",""), ".",",")),"Invalid")) -> 3 | AC52: =COUNTIF($A$2:$A$103,A53) -> 1 | AE52: =COUNTIF(messy_ecommerce_sales_data__2[Order_ID],'01_Raw'!C54) -> 1 | AG52: =IFERROR(AA52*Y52,"Cannot Calculate") -> 699.33 | AH52: =IF(AG52='01_Raw'!K53,"OK","Mismatch") -> Mismatch | AJ52: =IF(LEN(TRIM(AG52)) = 0, "Missing",IFERROR(VALUE(SUBSTITUTE(SUBSTITUTE(AG52,"$",""), ".",",")),"Invalid")) -> 699.33 | AK52: =IF(AJ52=AG52,"OK","Mismatch") -> OK
A53: ='01_Raw'!A54 -> 152 | B53: =TRIM('01_Raw'!B54) -> Customer_152 | D53: =IFERROR(DATE(Q52,P52,R52),"Invalid") -> 45922 | E53: =TRIM('01_Raw'!E54) -> Lamp | F53: =IF(PROPER(TRIM('01_Raw'!F54))="Electronic","Electronics",PROPER(TRIM('01_Raw'!F54))) -> Home | I53: =TRIM('01_Raw'!I54) -> PayPal | J53: =TRIM('01_Raw'!J54) -> Returned | N53: =ISNUMBER('01_Raw'!D55) -> FALSE | P53: =LEFT('01_Raw'!D55, FIND("/",'01_Raw'!D55) - 1) -> 7 | Q53: =IFERROR(RIGHT('01_Raw'!D55,4),"Invalid") -> 2025 | R53: =MID('01_Raw'!D55,FIND("/",'01_Raw'!D55) + 1,FIND("/",'01_Raw'!D55,FIND("/",'01_Raw'!D55)+1)-FIND("/",'01_Raw'!D55)-1) -> 16 | S53: =IFERROR(DATE(Q53,P53,R53),"Invalid") -> 45854 | U53: =IFERROR(VALUE(SUBSTITUTE(SUBSTITUTE('01_Raw'!H55,"$",""), ".",",")),"Invalid") -> 278.9 | V53: =IFERROR(VALUE('01_Raw'!G55), "Invalid") -> 4 | X53: =IF(ISBLANK('01_Raw'!H55),"Missing", IFERROR(VALUE(SUBSTITUTE(SUBSTITUTE('01_Raw'!H55,"$",""), ".",",")),"Invalid")) -> 278.9 | Y53: =IF(LEN(TRIM('01_Raw'!H55)) = 0, "Missing",IFERROR(VALUE(SUBSTITUTE(SUBSTITUTE('01_Raw'!H55,"$",""), ".",",")),"Invalid")) -> 278.9 | AA53: =IF(LEN(TRIM('01_Raw'!G55)) = 0, "Missing",IFERROR(VALUE(SUBSTITUTE(SUBSTITUTE('01_Raw'!G55,"$",""), ".",",")),"Invalid")) -> 4 | AC53: =COUNTIF($A$2:$A$103,A54) -> 1 | AE53: =COUNTIF(messy_ecommerce_sales_data__2[Order_ID],'01_Raw'!C55) -> 1 | AG53: =IFERROR(AA53*Y53,"Cannot Calculate") -> 1115.6 | AH53: =IF(AG53='01_Raw'!K54,"OK","Mismatch") -> Mismatch | AJ53: =IF(LEN(TRIM(AG53)) = 0, "Missing",IFERROR(VALUE(SUBSTITUTE(SUBSTITUTE(AG53,"$",""), ".",",")),"Invalid")) -> 1115.6 | AK53: =IF(AJ53=AG53,"OK","Mismatch") -> OK
A54: ='01_Raw'!A55 -> 153 | B54: =TRIM('01_Raw'!B55) -> Customer_153 | D54: =IFERROR(DATE(Q53,P53,R53),"Invalid") -> 45854 | E54: =TRIM('01_Raw'!E55) -> Yoga Mat | F54: =IF(PROPER(TRIM('01_Raw'!F55))="Electronic","Electronics",PROPER(TRIM('01_Raw'!F55))) -> Sports | I54: =TRIM('01_Raw'!I55) -> Cash on Delivery | J54: =TRIM('01_Raw'!J55) -> Processing | N54: =ISNUMBER('01_Raw'!D56) -> FALSE | P54: =LEFT('01_Raw'!D56, FIND("/",'01_Raw'!D56) - 1) -> 2 | Q54: =IFERROR(RIGHT('01_Raw'!D56,4),"Invalid") -> 2025 | R54: =MID('01_Raw'!D56,FIND("/",'01_Raw'!D56) + 1,FIND("/",'01_Raw'!D56,FIND("/",'01_Raw'!D56)+1)-FIND("/",'01_Raw'!D56)-1) -> 21 | S54: =IFERROR(DATE(Q54,P54,R54),"Invalid") -> 45709 | U54: =IFERROR(VALUE(SUBSTITUTE(SUBSTITUTE('01_Raw'!H56,"$",""), ".",",")),"Invalid") -> 789.64 | V54: =IFERROR(VALUE('01_Raw'!G56), "Invalid") -> 5 | X54: =IF(ISBLANK('01_Raw'!H56),"Missing", IFERROR(VALUE(SUBSTITUTE(SUBSTITUTE('01_Raw'!H56,"$",""), ".",",")),"Invalid")) -> 789.64 | Y54: =IF(LEN(TRIM('01_Raw'!H56)) = 0, "Missing",IFERROR(VALUE(SUBSTITUTE(SUBSTITUTE('01_Raw'!H56,"$",""), ".",",")),"Invalid")) -> 789.64 | AA54: =IF(LEN(TRIM('01_Raw'!G56)) = 0, "Missing",IFERROR(VALUE(SUBSTITUTE(SUBSTITUTE('01_Raw'!G56,"$",""), ".",",")),"Invalid")) -> 5 | AC54: =COUNTIF($A$2:$A$103,A55) -> 1 | AE54: =COUNTIF(messy_ecommerce_sales_data__2[Order_ID],'01_Raw'!C56) -> 1 | AG54: =IFERROR(AA54*Y54,"Cannot Calculate") -> 3948.2 | AH54: =IF(AG54='01_Raw'!K55,"OK","Mismatch") -> Mismatch | AJ54: =IF(LEN(TRIM(AG54)) = 0, "Missing",IFERROR(VALUE(SUBSTITUTE(SUBSTITUTE(AG54,"$",""), ".",",")),"Invalid")) -> 3948.2 | AK54: =IF(AJ54=AG54,"OK","Mismatch") -> OK
A55: ='01_Raw'!A56 -> 154 | B55: =TRIM('01_Raw'!B56) -> Customer_154 | D55: =IFERROR(DATE(Q54,P54,R54),"Invalid") -> 45709 | E55: =TRIM('01_Raw'!E56) -> Blender | F55: =IF(PROPER(TRIM('01_Raw'!F56))="Electronic","Electronics",PROPER(TRIM('01_Raw'!F56))) -> Home | I55: =TRIM('01_Raw'!I56) -> Cash on Delivery | J55: =TRIM('01_Raw'!J56) -> Cancelled | N55: =ISNUMBER('01_Raw'!D57) -> FALSE | P55: =LEFT('01_Raw'!D57, FIND("/",'01_Raw'!D57) - 1) -> 5 | Q55: =IFERROR(RIGHT('01_Raw'!D57,4),"Invalid") -> 2025 | R55: =MID('01_Raw'!D57,FIND("/",'01_Raw'!D57) + 1,FIND("/",'01_Raw'!D57,FIND("/",'01_Raw'!D57)+1)-FIND("/",'01_Raw'!D57)-1) -> 1 | S55: =IFERROR(DATE(Q55,P55,R55),"Invalid") -> 45778 | U55: =IFERROR(VALUE(SUBSTITUTE(SUBSTITUTE('01_Raw'!H57,"$",""), ".",",")),"Invalid") -> 40.95 | V55: =IFERROR(VALUE('01_Raw'!G57), "Invalid") -> 1 | X55: =IF(ISBLANK('01_Raw'!H57),"Missing", IFERROR(VALUE(SUBSTITUTE(SUBSTITUTE('01_Raw'!H57,"$",""), ".",",")),"Invalid")) -> 40.95 | Y55: =IF(LEN(TRIM('01_Raw'!H57)) = 0, "Missing",IFERROR(VALUE(SUBSTITUTE(SUBSTITUTE('01_Raw'!H57,"$",""), ".",",")),"Invalid")) -> 40.95 | AA55: =IF(LEN(TRIM('01_Raw'!G57)) = 0, "Missing",IFERROR(VALUE(SUBSTITUTE(SUBSTITUTE('01_Raw'!G57,"$",""), ".",",")),"Invalid")) -> 1 | AC55: =COUNTIF($A$2:$A$103,A56) -> 1 | AE55: =COUNTIF(messy_ecommerce_sales_data__2[Order_ID],'01_Raw'!C57) -> 1 | AG55: =IFERROR(AA55*Y55,"Cannot Calculate") -> 40.95 | AH55: =IF(AG55='01_Raw'!K56,"OK","Mismatch") -> Mismatch | AJ55: =IF(LEN(TRIM(AG55)) = 0, "Missing",IFERROR(VALUE(SUBSTITUTE(SUBSTITUTE(AG55,"$",""), ".",",")),"Invalid")) -> 40.95 | AK55: =IF(AJ55=AG55,"OK","Mismatch") -> OK
... A102: ='01_Raw'!A103 -> 142 | B102: =TRIM('01_Raw'!B103) -> Customer_142 | D102: =IFERROR(DATE(Q101,P101,R101),"Invalid") -> 45960 | E102: =TRIM('01_Raw'!E103) -> Shoes | F102: =IF(PROPER(TRIM('01_Raw'!F103))="Electronic","Electronics",PROPER(TRIM('01_Raw'!F103))) -> Clothing | I102: =TRIM('01_Raw'!I103) -> Credit Card | J102: =TRIM('01_Raw'!J103) -> Shipped | N102: =ISNUMBER('01_Raw'!D104) -> FALSE | P102: =LEFT('01_Raw'!D104, FIND("/",'01_Raw'!D104) - 1) -> 7 | Q102: =IFERROR(RIGHT('01_Raw'!D104,4),"Invalid") -> 2025 | R102: =MID('01_Raw'!D104,FIND("/",'01_Raw'!D104) + 1,FIND("/",'01_Raw'!D104,FIND("/",'01_Raw'!D104)+1)-FIND("/",'01_Raw'!D104)-1) -> 9 | S102: =IFERROR(DATE(Q102,P102,R102),"Invalid") -> 45847 | U102: =IFERROR(VALUE(SUBSTITUTE(SUBSTITUTE('01_Raw'!H104,"$",""), ".",",")),"Invalid") -> 705.42 | V102: =IFERROR(VALUE('01_Raw'!G104), "Invalid") -> 2 | X102: =IF(ISBLANK('01_Raw'!H104),"Missing", IFERROR(VALUE(SUBSTITUTE(SUBSTITUTE('01_Raw'!H104,"$",""), ".",",")),"Invalid")) -> 705.42 | Y102: =IF(LEN(TRIM('01_Raw'!H104)) = 0, "Missing",IFERROR(VALUE(SUBSTITUTE(SUBSTITUTE('01_Raw'!H104,"$",""), ".",",")),"Invalid")) -> 705.42 | AA102: =IF(LEN(TRIM('01_Raw'!G104)) = 0, "Missing",IFERROR(VALUE(SUBSTITUTE(SUBSTITUTE('01_Raw'!G104,"$",""), ".",",")),"Invalid")) -> 2 | AC102: =COUNTIF($A$2:$A$103,A103) -> 2 | AE102: =COUNTIF(messy_ecommerce_sales_data__2[Order_ID],'01_Raw'!C104) -> 2 | AG102: =IFERROR(AA102*Y102,"Cannot Calculate") -> 1410.84 | AH102: =IF(AG102='01_Raw'!K103,"OK","Mismatch") -> Mismatch | AJ102: =IF(LEN(TRIM(AG102)) = 0, "Missing",IFERROR(VALUE(SUBSTITUTE(SUBSTITUTE(AG102,"$",""), ".",",")),"Invalid")) -> 1410.84 | AK102: =IF(AJ102=AG102,"OK","Mismatch") -> OK
A103: ='01_Raw'!A104 -> 146 | B103: =TRIM('01_Raw'!B104) -> Customer_146 | D103: =IFERROR(DATE(Q102,P102,R102),"Invalid") -> 45847 | E103: =TRIM('01_Raw'!E104) -> Basketball | F103: =IF(PROPER(TRIM('01_Raw'!F104))="Electronic","Electronics",PROPER(TRIM('01_Raw'!F104))) -> Electronics | I103: =TRIM('01_Raw'!I104) -> Bank Transfer | J103: =TRIM('01_Raw'!J104) -> Processing | N103: =ISNUMBER('01_Raw'!D105) -> FALSE | P103: =LEFT('01_Raw'!D105, FIND("/",'01_Raw'!D105) - 1) -> #VALUE! | Q103: =IFERROR(RIGHT('01_Raw'!D105,4),"Invalid") | R103: =MID('01_Raw'!D105,FIND("/",'01_Raw'!D105) + 1,FIND("/",'01_Raw'!D105,FIND("/",'01_Raw'!D105)+1)-FIND("/",'01_Raw'!D105)-1) -> #VALUE! | S103: =IFERROR(DATE(Q103,P103,R103),"Invalid") -> Invalid | U103: =IFERROR(VALUE(SUBSTITUTE(SUBSTITUTE('01_Raw'!H105,"$",""), ".",",")),"Invalid") -> Invalid | V103: =IFERROR(VALUE('01_Raw'!G105), "Invalid") -> 0 | X103: =IF(ISBLANK('01_Raw'!H105),"Missing", IFERROR(VALUE(SUBSTITUTE(SUBSTITUTE('01_Raw'!H105,"$",""), ".",",")),"Invalid")) -> Missing | Y103: =IF(LEN(TRIM('01_Raw'!H105)) = 0, "Missing",IFERROR(VALUE(SUBSTITUTE(SUBSTITUTE('01_Raw'!H105,"$",""), ".",",")),"Invalid")) -> Missing | AA103: =IF(LEN(TRIM('01_Raw'!G105)) = 0, "Missing",IFERROR(VALUE(SUBSTITUTE(SUBSTITUTE('01_Raw'!G105,"$",""), ".",",")),"Invalid")) -> Missing | AC103: =COUNTIF($A$2:$A$103,A104) -> 0 | AE103: =COUNTIF(messy_ecommerce_sales_data__2[Order_ID],'01_Raw'!C105) -> 0

Sheet 03_Clean_Formulas.
A1: ID | B1: Customer_Name | C1: Order_ID | D1: Order_Date | E1: Product | F1: Category | G1: Quantity | H1: Price | I1: Payment_Method | J1: Status | K1: Total | M1: Category_Clean | N1: Date_Clean | O1: Quantity_Clean | P1: Price_Clean | Q1: Total_Clean | R1: Total_calc | S1: Check
A2: 100 | B2: Customer_100 | C2: ORD-41285 | D2: 11/22/2024 | E2: Blender | F2: Home | G2: 3 | H2: 38 | I2: Cash on Delivery | J2: Shipped | K2: 114 | M2: =IF(OR(F2="",F2="Nan"),"Missing",IF(PROPER(TRIM(messy_ecommerce_sales_data__27[[#This Row],[ Category]]))="Electronic","Electronics",PROPER(TRIM(messy_ecommerce_sales_data__27[[#This Row],[ Category]])))) -> Home | N2: 45618 | O2: =IF(LEN(TRIM(messy_ecommerce_sales_data__27[[#This Row],[Quantity]])) = 0, "Missing",IFERROR(VALUE(messy_ecommerce_sales_data__27[[#This Row],[Quantity]]),"Invalid")) -> 3 | P2: =IFERROR(VALUE(SUBSTITUTE(SUBSTITUTE(H2,"$",""), ".",",")),"Invalid") -> 38 | Q2: =IF(LEN(TRIM(messy_ecommerce_sales_data__27[[#This Row],[Total]])) = 0, "Missing",IFERROR(VALUE(SUBSTITUTE(SUBSTITUTE(messy_ecommerce_sales_data__27[[#This Row],[Total]],"$",""), ".",",")),"Invalid")) -> 114 | R2: =IFERROR(O2*P2, "Cannot Calculate") -> 114 | S2: =IF(AND(ISNUMBER(R2),ISNUMBER(Q2)),IF(ROUND(R2,2)=ROUND(Q2,2),"OK","Mismatch"),"No Data") -> OK
A3: 101 | B3: Customer_101 | C3: ORD-35783 | D3: 7/5/2025 | E3: Smartphone | F3: Electronics | G3: 2 | H3: abd | I3: PayPal | J3: Processing | M3: =IF(OR(F3="",F3="Nan"),"Missing",IF(PROPER(TRIM(messy_ecommerce_sales_data__27[[#This Row],[ Category]]))="Electronic","Electronics",PROPER(TRIM(messy_ecommerce_sales_data__27[[#This Row],[ Category]])))) -> Electronics | N3: 45843 | O3: =IF(LEN(TRIM(messy_ecommerce_sales_data__27[[#This Row],[Quantity]])) = 0, "Missing",IFERROR(VALUE(messy_ecommerce_sales_data__27[[#This Row],[Quantity]]),"Invalid")) -> 2 | P3: =IFERROR(VALUE(SUBSTITUTE(SUBSTITUTE(H3,"$",""), ".",",")),"Invalid") -> Invalid | Q3: =IF(LEN(TRIM(messy_ecommerce_sales_data__27[[#This Row],[Total]])) = 0, "Missing",IFERROR(VALUE(SUBSTITUTE(SUBSTITUTE(messy_ecommerce_sales_data__27[[#This Row],[Total]],"$",""), ".",",")),"Invalid")) -> Missing | R3: =IFERROR(O3*P3, "Cannot Calculate") -> Cannot Calculate | S3: =IF(AND(ISNUMBER(R3),ISNUMBER(Q3)),IF(ROUND(R3,2)=ROUND(Q3,2),"OK","Mismatch"),"No Data") -> No Data
A4: 102 | B4: Customer_102 | C4: ORD-84355 | D4: 12/23/2024 | E4: Tennis Racket | F4: Sports | G4: 1 | H4: 389.05 | I4: PayPal | J4: Delivered | K4: 389.05 | M4: =IF(OR(F4="",F4="Nan"),"Missing",IF(PROPER(TRIM(messy_ecommerce_sales_data__27[[#This Row],[ Category]]))="Electronic","Electronics",PROPER(TRIM(messy_ecommerce_sales_data__27[[#This Row],[ Category]])))) -> Sports | N4: 45649 | O4: =IF(LEN(TRIM(messy_ecommerce_sales_data__27[[#This Row],[Quantity]])) = 0, "Missing",IFERROR(VALUE(messy_ecommerce_sales_data__27[[#This Row],[Quantity]]),"Invalid")) -> 1 | P4: =IFERROR(VALUE(SUBSTITUTE(SUBSTITUTE(H4,"$",""), ".",",")),"Invalid") -> 389.05 | Q4: =IF(LEN(TRIM(messy_ecommerce_sales_data__27[[#This Row],[Total]])) = 0, "Missing",IFERROR(VALUE(SUBSTITUTE(SUBSTITUTE(messy_ecommerce_sales_data__27[[#This Row],[Total]],"$",""), ".",",")),"Invalid")) -> 389.05 | R4: =IFERROR(O4*P4, "Cannot Calculate") -> 389.05 | S4: =IF(AND(ISNUMBER(R4),ISNUMBER(Q4)),IF(ROUND(R4,2)=ROUND(Q4,2),"OK","Mismatch"),"No Data") -> OK
